Workbook

Sheet ADMK
B2: d7fb35bb-cd73-4619-ab55-6dd15091f242
B3: id | C3: Sl No. | D3: Candidate name | E3: Constituency name | G3: Assembly Constituency Name | H3: Candidate Name | J3: =_xlfn.CONCAT("insert into candidate (id, year, party_id, constituency_id, candidate_name, created_by) values (UUID(), 2026, '", $B$2, "', '", B4, "', '", D4, "', 'system' );") -> insert into candidate (id, year, party_id, constituency_id, candidate_name, created_by) values (UUID(), 2026, 'd7fb35bb-cd73-4619-ab55-6dd15091f242', 'b23bc17c-3c90-42e5-acda-75cbd383845e', 'V. Sudhakar', 'system' );
B4: =VLOOKUP(F4,'TN Constituency'!P:Q,2,FALSE) -> b23bc17c-3c90-42e5-acda-75cbd383845e | C4: 1 | D4: V. Sudhakar | E4: 1 - Gummidipoondi | F4: Gummidipoondi | G4: Edappadi | H4: K. Palaniswami
B5: =VLOOKUP(F5,'TN Constituency'!P:Q,2,FALSE) -> 3a716a0f-b4b9-457f-a3a1-a66c6888fe7a | C5: 2 | D5: Siruniyam P. Balaraman | E5: 2 - Ponneri | F5: Ponneri | G5: Veppanahalli | H5: K.P. Munusamy
B6: =VLOOKUP(F6,'TN Constituency'!P:Q,2,FALSE) -> e0a00a3b-90f6-4696-9e59-caa742168983 | C6: 3 | D6: K. Hari | E6: 3 - Tiruttani | F6: Tiruttani | G6: Thindukkal | H6: C. Srinivasan
B7: =VLOOKUP(F7,'TN Constituency'!P:Q,2,FALSE) -> 008aedf6-4a9d-4269-a7ad-63b7e8d8eaa5 | C7: 4 | D7: B. V. Ramana | E7: 4 - Thiruvallur | F7: Thiruvallur | G7: Natham | H7: Natham R. Viswanathan
B8: =VLOOKUP(F8,'TN Constituency'!P:Q,2,FALSE) -> b5f82308-ca4e-41c1-9499-e932b5b6705d | C8: 5 | D8: Benjamin | E8: 7 - Maduravoyal | F8: Maduravoyal | G8: Thondamuthur | H8: S.P. Velumani
B9: =VLOOKUP(F9,'TN Constituency'!P:Q,2,FALSE) -> 52619af0-424d-4172-9451-f329734d5a34 | C9: 6 | D9: V. Moorthy | E9: 9 - Madavaram | F9: Madavaram | G9: Kumarapalayam | H9: P. Thangamani
B10: =VLOOKUP(F10,'TN Constituency'!P:Q,2,FALSE) -> 7ab4491b-648d-48c5-bcac-781f3095e9b3 | C10: 7 | D10: K. Kuppan | E10: 10 - Thiruvottiyur | F10: Thiruvottiyur | G10: Rayapuram | H10: D. Jayakumar
B11: =VLOOKUP(F11,'TN Constituency'!P:Q,2,FALSE) -> 499ff327-af5f-4703-8e77-8a22e71fb2c3 | C11: 8 | D11: R. S. Rajesh | E11: 11 - Dr.Radhakrishnan Nagar | F11: Dr.Radhakrishnan Nagar | G11: Mailam | H11: C.Ve. Shanmugam
B12: =VLOOKUP(F12,'TN Constituency'!P:Q,2,FALSE) -> 3236346d-b10c-4aff-9ce3-c46583b10191 | C12: 9 | D12: P. Santhanakrishnan | E12: 13 - Kolathur | F12: Kolathur | G12: Madurai West | H12: Sellur K. Raju
B13: =VLOOKUP(F13,'TN Constituency'!P:Q,2,FALSE) -> 07df490e-071b-4a61-87ff-347bb52f532b | C13: 10 | D13: Vijayakumar | E13: 14 - Villivakkam | F13: Villivakkam | G13: Palacode | H13: K.P. Anbazhagan
B14: =VLOOKUP(F14,'TN Constituency'!P:Q,2,FALSE) -> 30ac3795-6700-480f-b3b4-695d1d7fb7d9 | C14: 11 | D14: A. Porkodi | E14: 15 - Thiru-Vi-Ka-Nagar | F14: Thiru-Vi-Ka-Nagar | G14: Nannilam | H14: R. Kamaraj
B15: =VLOOKUP(F15,'TN Constituency'!P:Q,2,FALSE) -> e9d7b055-673a-4a10-a667-ba540eb89569 | C15: 12 | D15: Abhishek Rangaswamy | E15: 16 - Egmore | F15: Egmore | G15: Vedaranyam | H15: O.S. Manian
... B170: =VLOOKUP(F170,'TN Constituency'!P:Q,2,FALSE) -> e917a474-283e-411f-8f86-3f787f4765e7 | C170: 167 | D170: S. Sayed Sultan Samsudeen | E170: 226 - Palayamkottai | F170: Palayamkottai | G170: Alangudi (182) | H170: Mr. Dhan. Vimal, B.A., B.L.; Pudukkottai North District Puratchi Thalaivi Peravai Joint Secretary
B171: =VLOOKUP(F171,'TN Constituency'!P:Q,2,FALSE) -> 22e64e27-1dc1-4398-8a07-bbfc6e10b177 | C171: 168 | D171: N. Thalavaisundaram | E171: 229 - Kanniyakumari | F171: Kanniyakumari

Sheet DMK
B2: 4bdabcb3-ac2c-4b4b-a218-d7d66f64fd0d | H2: Dravida Munnetra Kazhagam (DMK)
B3: DMK | N3: id | O3: year | P3: party_id | Q3: candidate_name | R3: constituency_id | S3: district_id | T3: state_id | U3: country_id
H4: id | I4: year | J4: party_id | K4: constituency_id
B5: S.No | C5: Constituency | D5: Candidate Name | G5: Sl No. | H5: Candidate name | I5: Constituency name
B6: 1 | C6: Kanniyakumari | D6: Re. Mahesh B.A., B.L. | G6: 1 | H6: Govindarajan | I6: 1 - Gummidipoondi | K6: =VLOOKUP(L6,'TN Constituency'!P:Q,2,FALSE) -> b23bc17c-3c90-42e5-acda-75cbd383845e | L6: Gummidipoondi | M6: =VLOOKUP(L6,C:D,2,FALSE) -> T.J. Govindarajan
B7: 2 | C7: Nagercoil | D7: S. Austin M.A. | G7: 2 | H7: Rajendran | I7: 4 - Thiruvallur | K7: =VLOOKUP(L7,'TN Constituency'!P:Q,2,FALSE) -> 008aedf6-4a9d-4269-a7ad-63b7e8d8eaa5 | L7: Thiruvallur | M7: =VLOOKUP(L7,C:D,2,FALSE) -> V.G. Rajendran B.E.
B8: 3 | C8: Radhapuram | D8: M. Appavu | G8: 3 | H8: Krishnasamy | I8: 5 - Poonamallee | K8: =VLOOKUP(L8,'TN Constituency'!P:Q,2,FALSE) -> 17586e3c-1487-43c6-81b0-e3cabe59fa92 | L8: Poonamallee | M8: =VLOOKUP(L8,C:D,2,FALSE) -> A. Krishnaswamy B.A., B.L.
B9: 4 | C9: Palayamkottai | D9: M. Abdul Wahab B.Com. | G9: 4 | H9: SM. Nasar | I9: 6 - Avadi | K9: =VLOOKUP(L9,'TN Constituency'!P:Q,2,FALSE) -> 4987680d-e88c-4439-a3ae-1a536e586453 | L9: Avadi | M9: =VLOOKUP(L9,C:D,2,FALSE) -> S.M. Nasar
B10: 5 | C10: Tirunelveli | D10: Su. Subramanian B.E., M.B.A. | G10: 5 | H10: Gaarampakkam Ganapathi | I10: 7 - Maduravoyal | K10: =VLOOKUP(L10,'TN Constituency'!P:Q,2,FALSE) -> b5f82308-ca4e-41c1-9499-e932b5b6705d | L10: Maduravoyal | M10: =VLOOKUP(L10,C:D,2,FALSE) -> Karambakkam Ganapathy
B11: 6 | C11: Alangulam | D11: Dr. Paul Manoj Pandian M.A., M.L., Ph.D. | G11: 6 | H11: Dr. Poornima | I11: 8 - Ambattur | K11: =VLOOKUP(L11,'TN Constituency'!P:Q,2,FALSE) -> bcfb125e-6b85-4f11-a08f-902adff330bf | L11: Ambattur | M11: =VLOOKUP(L11,C:D,2,FALSE) -> Dr. A.P. Poornima M.B.B.S., M.D.
B12: 7 | C12: Tenkasi | D12: Dr. Kalai Kathiravan M.B.B.S. | G12: 7 | H12: Sudarsanam | I12: 9 - Madavaram | K12: =VLOOKUP(L12,'TN Constituency'!P:Q,2,FALSE) -> 52619af0-424d-4172-9451-f329734d5a34 | L12: Madavaram | M12: S. Sudharsanam M.A., B.L.
B13: 8 | C13: Vasudevanallur | D13: E. Raja B.Com., M.L. | G13: 8 | H13: Ebinezhar | I13: 11 - Dr.Radhakrishnan Nagar | K13: =VLOOKUP(L13,'TN Constituency'!P:Q,2,FALSE) -> 499ff327-af5f-4703-8e77-8a22e71fb2c3 | L13: Dr.Radhakrishnan Nagar | M13: =VLOOKUP(L13,C:D,2,FALSE) -> J.J. Ebenezer M.Com., B.L.
B14: 9 | C14: Kovilpatti | D14: Ka. Karunanithi | G14: 9 | H14: RD Sekar | I14: 12 - Perambur | K14: =VLOOKUP(L14,'TN Constituency'!P:Q,2,FALSE) -> 144532f7-7933-491e-8f75-8444036f8e76 | L14: Perambur | M14: =VLOOKUP(L14,C:D,2,FALSE) -> R.D. Sekar B.Com., B.L.
B15: 10 | C15: Ottapidaram | D15: M.C. Shanmugiah B.Sc. | G15: 10 | H15: MK. Stalin | I15: 13 - Kolathur | K15: =VLOOKUP(L15,'TN Constituency'!P:Q,2,FALSE) -> 3236346d-b10c-4aff-9ce3-c46583b10191 | L15: Kolathur | M15: =VLOOKUP(L15,C:D,2,FALSE) -> Muthuvel Karunanidhi Stalin B.A.
B16: 11 | C16: Tiruchendur | D16: Anitha Radhakrishnan | G16: 11 | H16: Karthick Mohan | I16: 14 - Villivakkam | K16: =VLOOKUP(L16,'TN Constituency'!P:Q,2,FALSE) -> 07df490e-071b-4a61-87ff-347bb52f532b | L16: Villivakkam | M16: =VLOOKUP(L16,C:D,2,FALSE) -> Karthikeyan B.E., M.S.
B17: 12 | C17: Thoothukkudi | D17: Geetha Jeevan M.Com., B.Ed. | G17: 12 | H17: KS Ravichandran | I17: 15 - Thiru-Vi-Ka-Nagar | K17: =VLOOKUP(L17,'TN Constituency'!P:Q,2,FALSE) -> 30ac3795-6700-480f-b3b4-695d1d7fb7d9 | L17: Thiru-Vi-Ka-Nagar | M17: =VLOOKUP(L17,C:D,2,FALSE) -> K.S. Ravichandran B.Sc., B.L.
B18: 13 | C18: Vilathikulam | D18: G.V. Markandayan B.A., B.L. | G18: 13 | H18: Tamizhan Prasanna | I18: 16 - Egmore | K18: =VLOOKUP(L18,'TN Constituency'!P:Q,2,FALSE) -> e9d7b055-673a-4a10-a667-ba540eb89569 | L18: Egmore | M18: =VLOOKUP(L18,C:D,2,FALSE) -> I. Paranthamen B.L.
B19: 14 | C19: Mudhukulathur | D19: R.S. Rajakannappan B.Sc., B.L. | G19: 14 | H19: Dr. Suberkhan | I19: 17 - Royapuram | K19: =VLOOKUP(L19,'TN Constituency'!P:Q,2,FALSE) -> 249a1248-4592-483f-8dbe-3b525a49a3b5 | L19: Royapuram | M19: =VLOOKUP(L19,C:D,2,FALSE) -> Dr. Idream R. Murthy M.B.B.S.
B20: 15 | C20: Ramanathapuram | D20: Kaderbatcha (a) Muthuramalingam B.A. | G20: 15 | H20: PK. Sekar Babu | I20: 18 - Harbour | K20: =VLOOKUP(L20,'TN Constituency'!P:Q,2,FALSE) -> 699a5fbc-431e-4f7b-9fad-3a53be1bef5c | L20: Harbour | M20: =VLOOKUP(L20,C:D,2,FALSE) -> P.K. Sekar Babu
B21: 16 | C21: Paramakudi | D21: K.K. Kathiravan B.A., B.L. | G21: 16 | H21: Udhayanidhi Stalin | I21: 19 - Chepauk-Thiruvallikeni | K21: =VLOOKUP(L21,'TN Constituency'!P:Q,2,FALSE) -> 9f1f5173-0700-4a12-ae6b-23e4b140e8a7 | L21: Chepauk-Thiruvallikeni | M21: =VLOOKUP(L21,C:D,2,FALSE) -> Udhayanidhi Stalin B.Com.
B22: 17 | C22: Tiruchuli | D22: Thangam Thennarasu B.E. | G22: 17 | H22: Dr. Ezhilan Naganathan | I22: 20 - Thousand Lights | K22: =VLOOKUP(L22,'TN Constituency'!P:Q,2,FALSE) -> c7b04183-9ddf-4099-842a-41042c059d18 | L22: Thousand Lights | M22: =VLOOKUP(L22,C:D,2,FALSE) -> Dr. Ezhilan Naganathan M.B.B.S., M.D.
B23: 18 | C23: Aruppukkottai | D23: K.K.S.S.R. Ramachandran | G23: 18 | H23: Sitrarasu | I23: 21 - Anna Nagar | K23: =VLOOKUP(L23,'TN Constituency'!P:Q,2,FALSE) -> 0a5ca5e8-1e73-4ccc-92e4-42d2e7499dc8 | L23: Anna Nagar | M23: =VLOOKUP(L23,C:D,2,FALSE) -> M.K. Mohan
B24: 19 | C24: Sattur | D24: A.R.R. Raghuraman | G24: 19 | H24: Prabhakar Raja | I24: 22 - Virugampakkam | K24: =VLOOKUP(L24,'TN Constituency'!P:Q,2,FALSE) -> 2b785d52-83bd-45e0-b33d-b931873c69a2 | L24: Virugampakkam | M24: =VLOOKUP(L24,C:D,2,FALSE) -> Prabhakar Raja M.Tech., M.B.A.
B25: 20 | C25: Rajapalayam | D25: S. Thangapandian | G25: 20 | H25: Ma Subramanian | I25: 23 - Saidapet | K25: =VLOOKUP(L25,'TN Constituency'!P:Q,2,FALSE) -> acfcb782-eb05-4125-84fc-293fdd46247d | L25: Saidapet | M25: =VLOOKUP(L25,C:D,2,FALSE) -> Ma. Subramanian B.A., L.L.B.
B26: 21 | C26: Cumbum | D26: N. Ramakrishnan M.A. | G26: 21 | H26: Raja Anbazhagan | I26: 24 - Thiyagarayanagar | K26: =VLOOKUP(L26,'TN Constituency'!P:Q,2,FALSE) -> e48776e2-4649-407d-aa1a-b7e535d58691 | L26: Thiyagarayanagar | M26: Raja Anbazhagan B.Com.
B27: 22 | C27: Bodinayakanur | D27: O. Panneerselvam B.A. | G27: 22 | H27: Velu | I27: 25 - Mylapore | K27: =VLOOKUP(L27,'TN Constituency'!P:Q,2,FALSE) -> b3e6de9d-2023-49c1-8579-f087fa71a02a | L27: Mylapore | M27: =VLOOKUP(L27,C:D,2,FALSE) -> T. Velu B.A., L.L.B.
B28: 23 | C28: Andipatti | D28: A. Maharajan | G28: 23 | H28: Aravind Ramesh | I28: 27 - Shozhinganallur | K28: =VLOOKUP(L28,'TN Constituency'!P:Q,2,FALSE) -> bd9d5fa4-c604-4d86-b4a7-e587bdb4deeb | L28: Shozhinganallur | M28: S. Aravind Ramesh
B29: 24 | C29: Thirumangalam | D29: Sedapatti M. Manimaran | G29: 24 | H29: Tha. Mo. Anabarasan | I29: 28 - Alandur | K29: =VLOOKUP(L29,'TN Constituency'!P:Q,2,FALSE) -> ad8f07c3-9b27-47ce-9824-acba45495914 | L29: Alandur | M29: =VLOOKUP(L29,C:D,2,FALSE) -> T.M. Anbarasan
B30: 25 | C30: Thiruparankundram | D30: Krithika Thangapandian B.E. | G30: 25 | H30: Dr. RS. Krithika Devi | I30: 31 - Tambaram | K30: =VLOOKUP(L30,'TN Constituency'!P:Q,2,FALSE) -> 3ce24248-60ae-4e11-b3da-71b847a02cea | L30: Tambaram | M30: =VLOOKUP(L30,C:D,2,FALSE) -> Dr. S.R. Raja B.Sc.
B31: 26 | C31: Madurai West | D31: Raghu Balaji B.A., B.L. | G31: 26 | H31: Karthik Thandapani | I31: 32 - Chengalpattu | K31: =VLOOKUP(L31,'TN Constituency'!P:Q,2,FALSE) -> 835eaf84-e43d-4adc-8394-432342efb994 | L31: Chengalpattu | M31: =VLOOKUP(L31,C:D,2,FALSE) -> M.K.D. Karthik Dhandapani B.A., B.L.
B32: 27 | C32: Madurai Central | D32: Dr. P.T.R. Palanivel Thiagarajan B.Tech., M.S., Ph.D. | G32: 27 | H32: Amulu Ponmalar | I32: 35 - Madurantakam | K32: =VLOOKUP(L32,'TN Constituency'!P:Q,2,FALSE) -> fb842e08-f010-42ab-87cf-26a5ee23d2a5 | L32: Madurantakam | M32: =VLOOKUP(L32,C:D,2,FALSE) -> S. Amulu Ponmalar
B33: 28 | C33: Madurai North | D33: Go. Thalapathi | G33: 28 | H33: Sundar | I33: 36 - Uthiramerur | K33: =VLOOKUP(L33,'TN Constituency'!P:Q,2,FALSE) -> 3c964927-68f7-4aa4-87c1-b126ac7d928c | L33: Uthiramerur | M33: =VLOOKUP(L33,C:D,2,FALSE) -> K. Sundar B.Sc.
B34: 29 | C34: Sholavandan | D34: A. Venkatesan B.A. | G34: 29 | H34: Nithya Sukumar | I34: 37 - Kancheepuram | K34: =VLOOKUP(L34,'TN Constituency'!P:Q,2,FALSE) -> 89f28123-b93f-4db6-9bee-9cd807d47f94 | L34: Kancheepuram | M34: Nithya Sugumar
B35: 30 | C35: Madurai East | D35: P. Moorthy B.A. | G35: 30 | H35: Duraimurugan | I35: 40 - Katpadi | K35: =VLOOKUP(L35,'TN Constituency'!P:Q,2,FALSE) -> 7d3c2063-3254-4d91-87ba-94a938cd420d | L35: Katpadi | M35: =VLOOKUP(L35,C:D,2,FALSE) -> Duraimurugan M.A., B.L.
B36: 31 | C36: Manamadurai | D36: A. Tamilarasi Ravikumar B.Com. | G36: 31 | H36: Vinoth Gandhi | I36: 41 - Ranipet | K36: =VLOOKUP(L36,'TN Constituency'!P:Q,2,FALSE) -> 91bc257e-4e16-4cbe-87e4-bd31f2f58413 | L36: Ranipet | M36: =VLOOKUP(L36,C:D,2,FALSE) -> R. Gandhi
B37: 32 | C37: Tiruppattur | D37: K.R. Periakaruppan B.Com., B.L. | G37: 32 | H37: Eswarappan | I37: 42 - Arcot | K37: =VLOOKUP(L37,'TN Constituency'!P:Q,2,FALSE) -> 69fa24d2-050d-453c-9541-b00de0eddc10 | L37: Arcot | M37: =VLOOKUP(L37,C:D,2,FALSE) -> J.L. Eswarappan B.E.
B38: 33 | C38: Alangudi | D38: Siva. V. Meyyanathan M.C.A. | G38: 33 | H38: Karthikeyan | I38: 43 - Vellore | K38: =VLOOKUP(L38,'TN Constituency'!P:Q,2,FALSE) -> bbd38966-3332-4d40-b099-95809a23a002 | L38: Vellore | M38: =VLOOKUP(L38,C:D,2,FALSE) -> P. Karthikeyan
B39: 34 | C39: Thirumayam | D39: S. Regupathy B.Sc., B.L. | G39: 34 | H39: Nandha Kumar | I39: 44 - Anaikattu | K39: =VLOOKUP(L39,'TN Constituency'!P:Q,2,FALSE) -> ba90a866-2cf6-4c80-8721-b974b597081a | L39: Anaikattu | M39: A.P. Nandakumar M.A.
B40: 35 | C40: Pudukkottai | D40: Dr. Vai. Muthuraja M.B.B.S. | G40: 35 | H40: Dr. Rajeswari Mohan Gandhi | I40: 45 - Kilvaithinankuppam | K40: =VLOOKUP(L40,'TN Constituency'!P:Q,2,FALSE) -> 48e297af-c1e7-4445-81b9-647a05a54b69 | L40: Kilvaithinankuppam | M40: =VLOOKUP(L40,C:D,2,FALSE) -> Dr. Rajeswari Mohankandhi M.B.B.S.
B41: 36 | C41: Viralimalai | D41: K.K. Sellapandian M.Com., B.L. | G41: 36 | H41: Vilvanathan | I41: 48 - Ambur | K41: =VLOOKUP(L41,'TN Constituency'!P:Q,2,FALSE) -> 6f8dcb00-c491-4184-a5f0-16d9308fed04 | L41: Ambur | M41: =VLOOKUP(L41,C:D,2,FALSE) -> A.C. Vilvanathan
...

Sheet TVK
A1: TVK
B2: 544e531f-e2ac-4274-9305-c35164c1bd93
C4: Assembly Number | D4: Assembly Name | E4: Candidate Name | G4: S.No | H4: Constituency No. & Name | I4: Candidate Name (Designation)
C5: =VLOOKUP(D5,'TN Constituency'!P:Q,2,FALSE) -> b23bc17c-3c90-42e5-acda-75cbd383845e | D5: Gummidipoondi | E5: S. Vijayakumar | G5: 1 | H5: 12. Perambur | I5: Thiru. C. Joseph Vijay (Party President)
C6: =VLOOKUP(D6,'TN Constituency'!P:Q,2,FALSE) -> 3a716a0f-b4b9-457f-a3a1-a66c6888fe7a | D6: Ponneri | E6: Dr. M S Ravi | G6: 2 | H6: 141. Trichy East | I6: Thiru. C. Joseph Vijay (Party President)
C7: =VLOOKUP(D7,'TN Constituency'!P:Q,2,FALSE) -> e0a00a3b-90f6-4696-9e59-caa742168983 | D7: Tiruttani | E7: Dr. Sathyakumar | G7: 3 | H7: 24. T. Nagar | I7: Thiru. N. Anand Ex. MLA (Gen. Secretary)
C8: =VLOOKUP(D8,'TN Constituency'!P:Q,2,FALSE) -> 008aedf6-4a9d-4269-a7ad-63b7e8d8eaa5 | D8: Thiruvallur | E8: Dr. Arunkumar | G8: 4 | H8: 25. Mylapore | I8: Thiru. P. Venkataramanan (Treasurer)
C9: =VLOOKUP(D9,'TN Constituency'!P:Q,2,FALSE) -> 17586e3c-1487-43c6-81b0-e3cabe59fa92 | D9: Poonamallee | E9: R. Prakasam | G9: 5 | H9: 106. Gobichettipalayam | I9: Thiru. K.A. Sengottaiyan (Admin Committee)
C10: =VLOOKUP(D10,'TN Constituency'!P:Q,2,FALSE) -> 4987680d-e88c-4439-a3ae-1a536e586453 | D10: Avadi | E10: R. Rameshkumar | G10: 6 | H10: 14. Villivakkam | I10: Thiru. Adhav Arjuna (Gen. Secretary)
C11: =VLOOKUP(D11,'TN Constituency'!P:Q,2,FALSE) -> b5f82308-ca4e-41c1-9499-e932b5b6705d | D11: Maduravoyal | E11: P. Revanth Saran | G11: 7 | H11: 96. Tiruchengode | I11: Thiru. Dr. K.G. Arunkumar (Gen. Secretary)
C12: =VLOOKUP(D12,'TN Constituency'!P:Q,2,FALSE) -> bcfb125e-6b85-4f11-a08f-902adff330bf | D12: Ambattur | E12: G. Balamurugan | G12: 8 | H12: 195. Thiruparankundram | I12: Thiru. CTR Nirmal Kumar (Jt. Secretary)
C13: =VLOOKUP(D13,'TN Constituency'!P:Q,2,FALSE) -> 52619af0-424d-4172-9451-f329734d5a34 | D13: Madavaram | E13: M. L. Vijay Prabhu | G13: 9 | H13: 97. Kumarapalayam | I13: Thirumathi C. Vijayalakshmi (Dy. Gen. Secretary)
C14: =VLOOKUP(D14,'TN Constituency'!P:Q,2,FALSE) -> 7ab4491b-648d-48c5-bcac-781f3095e9b3 | D14: Thiruvottiyur | E14: Senthilkumar | G14: 10 | H14: 151. Tittakudi (SC) | I14: Thiru. A. Rajasekar (HQ Secretary)
C15: =VLOOKUP(D15,'TN Constituency'!P:Q,2,FALSE) -> 499ff327-af5f-4703-8e77-8a22e71fb2c3 | D15: Dr.Radhakrishnan Nagar | E15: Maria Wilson | G15: 11 | H15: 23. Saidapet | I15: Thiru. M. Arul Prakasam (Dy. Gen. Secretary)
C16: =VLOOKUP(D16,'TN Constituency'!P:Q,2,FALSE) -> 144532f7-7933-491e-8f75-8444036f8e76 | D16: Perambur | E16: C Joseph Vijay | G16: 12 | H16: 124. Valparai (SC) | I16: Thiru. Dr. A. Sridharan (Dy. Gen. Secretary)
... C238: =VLOOKUP(D238,'TN Constituency'!P:Q,2,FALSE) -> 227183fd-4356-4815-9f2b-51ccced152c5 | D238: Killiyoor | E238: S.Sabeer | G238: 234 | H238: 234. Killiyoor | I238: Thiru. S. Sivin (Dist. Secretary)

Sheet NTK
A1: NTK
B2: 4c3fc4aa-28bd-4385-a231-cbd9914b99db
C4: Sl No. | D4: Candidate name | E4: Constituency name | I4: Candidate Name | J4: Assembly Constituency
C5: =VLOOKUP(E5,'TN Constituency'!P:Q,2,FALSE) -> b23bc17c-3c90-42e5-acda-75cbd383845e | D5: Sridhar | E5: Gummidipoondi | G5: 1 | I5: R. Sridhar | J5: Gummidipoondi
C6: =VLOOKUP(E6,'TN Constituency'!P:Q,2,FALSE) -> 3a716a0f-b4b9-457f-a3a1-a66c6888fe7a | D6: Rajathi | E6: Ponneri | G6: 2 | I6: Rajathi | J6: Ponneri
C7: =VLOOKUP(E7,'TN Constituency'!P:Q,2,FALSE) -> e0a00a3b-90f6-4696-9e59-caa742168983 | D7: Chandran | E7: Tiruttani | G7: 3 | I7: S.S.Chandran | J7: Tiruttani
C8: =VLOOKUP(E8,'TN Constituency'!P:Q,2,FALSE) -> 008aedf6-4a9d-4269-a7ad-63b7e8d8eaa5 | D8: Senthil Kumar | E8: Thiruvallur | G8: 4 | I8: K.Senthil Kumar | J8: Thiruvallur (Tiruvallur)
C9: =VLOOKUP(E9,'TN Constituency'!P:Q,2,FALSE) -> 17586e3c-1487-43c6-81b0-e3cabe59fa92 | D9: Mehala | E9: Poonamallee | G9: 5 | I9: Mehala | J9: Poonamallee
C10: =VLOOKUP(E10,'TN Constituency'!P:Q,2,FALSE) -> 4987680d-e88c-4439-a3ae-1a536e586453 | D10: Punitha | E10: Avadi | G10: 6 | I10: Punitha | J10: Avadi
C11: =VLOOKUP(E11,'TN Constituency'!P:Q,2,FALSE) -> b5f82308-ca4e-41c1-9499-e932b5b6705d | D11: Revathi | E11: Maduravoyal | G11: 7 | I11: Revathi | J11: Maduravoyal
C12: =VLOOKUP(E12,'TN Constituency'!P:Q,2,FALSE) -> bcfb125e-6b85-4f11-a08f-902adff330bf | D12: Aadhithan | E12: Ambattur | G12: 8 | I12: Aadhithan | J12: Ambattur
C13: =VLOOKUP(E13,'TN Constituency'!P:Q,2,FALSE) -> 52619af0-424d-4172-9451-f329734d5a34 | D13: Kruthika Elumalai | E13: Madavaram | G13: 9 | I13: Kruthika Elumalai | J13: Madavaram
C14: =VLOOKUP(E14,'TN Constituency'!P:Q,2,FALSE) -> 7ab4491b-648d-48c5-bcac-781f3095e9b3 | D14: Sathya Baskar | E14: Thiruvottiyur | G14: 10 | I14: Sathya Baskar | J14: Thiruvottiyur
C15: =VLOOKUP(E15,'TN Constituency'!P:Q,2,FALSE) -> 499ff327-af5f-4703-8e77-8a22e71fb2c3 | D15: Vennila Thayumanavan | E15: Dr.Radhakrishnan Nagar | G15: 11 | I15: Vennila Thayumanavan | J15: Dr.Radhakrishnan Nagar
C16: =VLOOKUP(E16,'TN Constituency'!P:Q,2,FALSE) -> 144532f7-7933-491e-8f75-8444036f8e76 | D16: Vetrithamizhan | E16: Perambur | G16: 12 | I16: Vetrithamizhan | J16: Perambur
... C238: =VLOOKUP(E238,'TN Constituency'!P:Q,2,FALSE) -> 227183fd-4356-4815-9f2b-51ccced152c5 | D238: Himler | E238: Killiyoor | G238: 234 | I238: Himler | J238: Killiyoor

Sheet AMMK
B2: 46968f74-1159-4d42-9af6-5222e27a8dc5
B15: Sl No. | C15: Candidate name | D15: Constituency name
B16: =VLOOKUP(D16,'TN Constituency'!P:Q,2,FALSE) -> 17586e3c-1487-43c6-81b0-e3cabe59fa92 | C16: Ezhumalai | D16: Poonamallee | F16: 5 | H16: - | J16: Poonamallee
B17: =VLOOKUP(D17,'TN Constituency'!P:Q,2,FALSE) -> acfcb782-eb05-4125-84fc-293fdd46247d | C17: Senthamizhan | D17: Saidapet | F17: 23 | H17: - | J17: Saidapet
B18: =VLOOKUP(D18,'TN Constituency'!P:Q,2,FALSE) -> 7afb0c6b-7415-4a37-bc2f-52de9c9fb91c | C18: Ganasekaran | D18: Tirupattur | F18: 50 | H18: - | J18: Tirupattur
B19: =VLOOKUP(D19,'TN Constituency'!P:Q,2,FALSE) -> b0ba5386-4152-4838-892f-be64e53a1f0a | C19: Shanmugavelu | D19: Madathukulam | F19: 126 | H19: - | J19: Madathukulam
B20: =VLOOKUP(D20,'TN Constituency'!P:Q,2,FALSE) -> 219cefbf-b41b-49b6-be17-43f4ad426552 | C20: Thottiyan Rajasekaran | D20: Tiruchirappalli (West) | F20: 140 | H20: - | J20: Tiruchirappalli (West)
B21: =VLOOKUP(D21,'TN Constituency'!P:Q,2,FALSE) -> 12728561-9a40-4380-b91a-4eddcd1d2b38 | C21: S. Kamaraj | D21: Mannargudi | F21: 167 | H21: - | J21: Mannargudi
B22: =VLOOKUP(D22,'TN Constituency'!P:Q,2,FALSE) -> b6a169ac-5ac7-41ae-b65d-e2fa74df02a4 | C22: Velu Karthikeyan | D22: Thiruvaiyaru | F22: 173 | H22: - | J22: Thiruvaiyaru
B23: =VLOOKUP(D23,'TN Constituency'!P:Q,2,FALSE) -> 8f61f1bb-b1a5-4250-99be-50eaae7fabc4 | C23: Therpogi Pandi | D23: Karaikudi | F23: 184 | H23: - | J23: Karaikudi
B24: =VLOOKUP(D24,'TN Constituency'!P:Q,2,FALSE) -> 4686158a-85b8-4b25-b9e3-c0883bd0d13b | C24: Dr Kathirkamu | D24: Periyakulam | F24: 199 | H24: - | J24: Periyakulam
B25: =VLOOKUP(D25,'TN Constituency'!P:Q,2,FALSE) -> 8804e2ab-34a0-48b5-82e7-0ec4bb78f6e1 | C25: Sundararajan | D25: Ottapidaram | F25: 217 | H25: - | J25: Ottapidaram
B26: =VLOOKUP(D26,'TN Constituency'!P:Q,2,FALSE) -> 7c86579b-3006-411c-a709-caccd559f8eb | C26: Esakki Muthu | D26: Nanguneri | F26: 227 | H26: - | J26: Nanguneri

Sheet INC
B2: 9c6d7c03-3a48-4c3f-a0be-56d7135a5d52 | D2: Sl No. | E2: Candidate name | F2: Constituency name
D3: =VLOOKUP(F3,'TN Constituency'!P:Q,2,FALSE) -> 3a716a0f-b4b9-457f-a3a1-a66c6888fe7a | E3: Durai Chandrasekar | F3: Ponneri | H3: 2 | J3: - | L3: Ponneri
D4: =VLOOKUP(F4,'TN Constituency'!P:Q,2,FALSE) -> c33c5b03-58f9-4026-a61c-d51446248685 | E4: JMH Aassan Maulaana | F4: Velachery | H4: 26 | J4: - | L4: Velachery
D5: =VLOOKUP(F5,'TN Constituency'!P:Q,2,FALSE) -> c6a5fdc0-2b60-4dd6-8dc5-4bfe43d62eb8 | E5: Selvaperunthagai | F5: Sriperumbudur | H5: 29 | J5: - | L5: Sriperumbudur
D6: =VLOOKUP(F6,'TN Constituency'!P:Q,2,FALSE) -> b4afca63-3c36-494b-8f7a-308c74d24ef3 | E6: AM Munirathnam | F6: Sholingur | H6: 39 | J6: - | L6: Sholingur
D7: =VLOOKUP(F7,'TN Constituency'!P:Q,2,FALSE) -> 4d245889-7db0-4c0c-9c75-8faa7ee90ad8 | E7: R. Kuppu Samy | F7: Uthangarai | H7: 51 | J7: - | L7: Uthangarai
D8: =VLOOKUP(F8,'TN Constituency'!P:Q,2,FALSE) -> c29ae31c-868f-49d4-a9b3-cabbdf64b64b | E8: A. Chella Kumar | F8: Krishnagiri | H8: 53 | J8: - | L8: Krishnagiri
D9: =VLOOKUP(F9,'TN Constituency'!P:Q,2,FALSE) -> d6c06308-5b86-46df-8956-4f558d116b3f | E9: GKM Tamil Kumaran | F9: Pennagaram | H9: 58 | J9: - | L9: Pennagaram
D10: =VLOOKUP(F10,'TN Constituency'!P:Q,2,FALSE) -> 85b0bd77-4905-4c4e-8cee-e0da6b715825 | E10: SK Arthanari | F10: Attur | H10: 82 | J10: - | L10: Attur
D11: =VLOOKUP(F11,'TN Constituency'!P:Q,2,FALSE) -> e9bd3072-f627-4a14-9ade-769c9cdbdc8f | E11: Gopinath Planiyappan | F11: Erode (East) | H11: 98 | J11: - | L11: Erode (East)
D12: =VLOOKUP(F12,'TN Constituency'!P:Q,2,FALSE) -> 16763ecc-2564-4bca-a9e9-5bff8d701a06 | E12: B.Ramachandran | F12: Udhagamandalam | H12: 108 | J12: - | L12: Udhagamandalam
D13: =VLOOKUP(F13,'TN Constituency'!P:Q,2,FALSE) -> 23960e10-1f55-431c-8fac-52d86db014fb | E13: kP Surya Prakash | F13: Kavundampalayam | H13: 117 | J13: - | L13: Kavundampalayam
D14: =VLOOKUP(F14,'TN Constituency'!P:Q,2,FALSE) -> 8c3f155d-980c-4377-88ff-c267523606cc | E14: V. Shrinithi Naidu | F14: Singanallur | H14: 121 | J14: - | L14: Singanallur
... D30: =VLOOKUP(F30,'TN Constituency'!P:Q,2,FALSE) -> 227183fd-4356-4815-9f2b-51ccced152c5 | E30: S. Rajesh Kumar | F30: Killiyoor | H30: 234 | J30: - | L30: Killiyoor

Sheet BJP
B2: 8429928e-a9ab-4bfe-b836-b59444036688
C3: Sl No. | D3: Candidate name | E3: Constituency name
C4: =VLOOKUP(E4,'TN Constituency'!P:Q,2,FALSE) -> 4987680d-e88c-4439-a3ae-1a536e586453 | D4: M. Rajasimha Mahendra | E4: Avadi | G4: 6 | I4: - | K4: Avadi
C5: =VLOOKUP(E5,'TN Constituency'!P:Q,2,FALSE) -> b3e6de9d-2023-49c1-8579-f087fa71a02a | D5: Dr. Tamilisai Soundarrajan | E5: Mylapore | G5: 25 | I5: - | K5: Mylapore
C6: =VLOOKUP(E6,'TN Constituency'!P:Q,2,FALSE) -> 5914df7d-f2fa-4fd0-bd22-a322456fd00a | D6: Dr. Nagesh Kumar | E6: Thalli | G6: 56 | I6: - | K6: Thalli
C7: =VLOOKUP(E7,'TN Constituency'!P:Q,2,FALSE) -> 2fa2af64-ce4f-45b4-ad99-5593a3c00a27 | D7: C. Elumalai | E7: Tiruvannamalai | G7: 63 | I7: - | K7: Tiruvannamalai
C8: =VLOOKUP(E8,'TN Constituency'!P:Q,2,FALSE) -> 5e57634f-8259-45df-a3f3-2f91c5b884e6 | D8: Dr. S. D. Premkumar | E8: Rasipuram | G8: 92 | I8: - | K8: Rasipuram
C9: =VLOOKUP(E9,'TN Constituency'!P:Q,2,FALSE) -> ed801607-de07-48d1-b18d-51c1acb399f6 | D9: Kirthika Shivkumar | E9: Modakkurichi | G9: 100 | I9: - | K9: Modakkurichi
C10: =VLOOKUP(E10,'TN Constituency'!P:Q,2,FALSE) -> 16763ecc-2564-4bca-a9e9-5bff8d701a06 | D10: Bhojarajan | E10: Udhagamandalam | G10: 108 | I10: - | K10: Udhagamandalam
C11: =VLOOKUP(E11,'TN Constituency'!P:Q,2,FALSE) -> f62de6b6-88e3-4238-a22e-ae95a4501718 | D11: Dr. L. Murugan | E11: Avanashi | G11: 112 | I11: - | K11: Avanashi (SC)
C12: =VLOOKUP(E12,'TN Constituency'!P:Q,2,FALSE) -> a1e4a52b-bf7d-48dc-a7c8-64ba133a2da4 | D12: S. Thangaraj | E12: Tiruppur (South) | G12: 114 | I12: - | K12: Tiruppur (South)
C13: =VLOOKUP(E13,'TN Constituency'!P:Q,2,FALSE) -> 4eb64a68-0a3a-4e72-8e80-bd74ed85e060 | D13: Vanathi Srinivasan | E13: Coimbatore (North) | G13: 118 | I13: - | K13: Coimbatore (North)
C14: =VLOOKUP(E14,'TN Constituency'!P:Q,2,FALSE) -> 09d0fb51-e29e-4dd7-af2b-2cd4c9b76e1c | D14: Govi Chandru | E14: Thiruvarur | G14: 168 | I14: - | K14: Thiruvarur
C15: =VLOOKUP(E15,'TN Constituency'!P:Q,2,FALSE) -> 9d0af417-8e52-47cd-b156-0817edf94444 | D15: M. Muruganandam | E15: Thanjavur | G15: 174 | I15: - | K15: Thanjavur
... C30: =VLOOKUP(E30,'TN Constituency'!P:Q,2,FALSE) -> 7aefb83a-d544-4df0-9f13-3ddeaa717c5e | D30: S. Vijayadharani | E30: Vilavancode | G30: 233 | I30: - | K30: Vilavancode
C34: Assembly No. | D34: Assembly Name | E34: Name of the Candidate
C35: 6 | D35: Avadi | E35: Shri M. Rajasimha Mahindra (M. Ashwiinkumar)
C36: 25 | D36: Mylapore | E36: Smt. (Dr.) Tamilisai Soundararajan
C37: 56 | D37: Thalli | E37: Dr. Nagesh Kumar
C38: 63 | D38: Tiruvannamalai | E38: Shri C. Elumalai
C39: 92 | D39: Rasipuram (SC) | E39: Dr. S.D. Premkumar
C40: 100 | D40: Modakkurichi | E40: Smt. Kirthika Shivkumar
C41: 108 | D41: Udhagamandalam | E41: Shri Bhojarajan
C42: 112 | D42: Avanashi (SC) | E42: Dr. L. Murugan
C43: 114 | D43: Tiruppur (South) | E43: Shri S. Thangaraj
C44: 118 | D44: Coimbatore (North) | E44: Smt. Vanathi Srinivasan
C45: 168 | D45: Thiruvarur | E45: Shri Govi Chandru
C46: 174 | D46: Thanjavur | E46: Shri M. Muruganandam
... C61: 233 | D61: Vilavancode | E61: Smt. S. Vijayadharini

Sheet PMK
B2: 55070de8-3d03-4dcb-98bc-d2ab0d67bf6a
C3: Sl No. | D3: Candidate name | E3: Constituency name
C4: =VLOOKUP(E4,'TN Constituency'!P:Q,2,FALSE) -> bcfb125e-6b85-4f11-a08f-902adff330bf | D4: Sekar | E4: Ambattur | G4: 8 | I4: - | K4: Ambattur
C5: =VLOOKUP(E5,'TN Constituency'!P:Q,2,FALSE) -> 144532f7-7933-491e-8f75-8444036f8e76 | D5: Thilagabama | E5: Perambur | G5: 12 | I5: - | K5: Perambur
C6: =VLOOKUP(E6,'TN Constituency'!P:Q,2,FALSE) -> 8bf639a7-bca3-42f8-928c-d466c5679fd8 | D6: K. Balu | E6: Thiruporur | G6: 33 | I6: - | K6: Thiruporur
C7: =VLOOKUP(E7,'TN Constituency'!P:Q,2,FALSE) -> 3c964927-68f7-4aa4-87c1-b126ac7d928c | D7: P. Mahesh Kumar | E7: Uthiramerur | G7: 36 | I7: - | K7: Uthiramerur
C8: =VLOOKUP(E8,'TN Constituency'!P:Q,2,FALSE) -> b4afca63-3c36-494b-8f7a-308c74d24ef3 | D8: K. Saravanan | E8: Sholingur | G8: 39 | I8: - | K8: Sholingur
C9: =VLOOKUP(E9,'TN Constituency'!P:Q,2,FALSE) -> d6c06308-5b86-46df-8956-4f558d116b3f | D9: Padi V. Selvam | E9: Pennagaram | G9: 58 | I9: - | K9: Pennagaram
C10: =VLOOKUP(E10,'TN Constituency'!P:Q,2,FALSE) -> 336dc71b-ba67-4fd9-9c9c-8289c709cdf5 | D10: Sowmiya Anbumani | E10: Dharmapuri | G10: 59 | I10: - | K10: Dharmapuri
C11: =VLOOKUP(E11,'TN Constituency'!P:Q,2,FALSE) -> 74f207e7-e4fd-450e-8d77-26aeec86f93f | D11: CR Bhaskaran | E11: Polur | G11: 66 | I11: - | K11: Polur
C12: =VLOOKUP(E12,'TN Constituency'!P:Q,2,FALSE) -> 4b93b543-e28b-49f6-be19-09de444d43d9 | D12: Ganesh | E12: Gingee | G12: 70 | I12: - | K12: Gingee
C13: =VLOOKUP(E13,'TN Constituency'!P:Q,2,FALSE) -> a3e78c2b-9731-4faa-8345-1d7cc1512556 | D13: Sivakumar | E13: Vikravandi | G13: 75 | I13: - | K13: Vikravandi
C14: =VLOOKUP(E14,'TN Constituency'!P:Q,2,FALSE) -> 9417a184-5784-445a-b39c-3483f11c2c82 | D14: A.P. Chezhiyan | E14: Rishivandiyam | G14: 78 | I14: - | K14: Rishivandiyam
C15: =VLOOKUP(E15,'TN Constituency'!P:Q,2,FALSE) -> 71c3c459-2eeb-4256-9260-087aff06bc8d | D15: Karthi | E15: Salem (West) | G15: 88 | I15: - | K15: Salem (West)
... C21: =VLOOKUP(E21,'TN Constituency'!P:Q,2,FALSE) -> 561279b4-8257-4b07-ae5d-eaee5d7ad432 | D21: Vadivel Ravanan S | E21: Kilvelur | G21: 164 | I21: - | K21: Kilvelur

Sheet MDMK
C2: Sl No. | D2: Candidate name | E2: Constituency name
C3: 1 | D3: Senthil Nathan | E3: 100 - Modakkurichi
C4: 2 | D4: Senthil Selvan | E4: 160 - Sirkazhi
C5: 3 | D5: Boominathan | E5: 192 - Madurai South
C6: 4 | D6: Rajendran | E6: 221 - Kadayanallur

Sheet VCK
B2: 2ece8d6c-0ef7-4f6f-91f1-1d553482a28f
C3: VCK
C4: Sl No. | D4: Candidate name | E4: Constituency name
C5: =VLOOKUP(E5,'TN Constituency'!P:Q,2,FALSE) -> 8bf639a7-bca3-42f8-928c-d466c5679fd8 | D5: Panneer Doss | E5: Thiruporur | I5: 33 | K5: - | M5: Thiruporur
C6: =VLOOKUP(E6,'TN Constituency'!P:Q,2,FALSE) -> 92c11a80-61bf-41d8-ac06-ccda1453a110 | D6: Sindhanai Selvan | E6: Cheyyur | I6: 34 | K6: - | M6: Cheyyur
C7: =VLOOKUP(E7,'TN Constituency'!P:Q,2,FALSE) -> 3cf53256-ea4a-4536-81f5-78fcf5d61d52 | D7: Ezhil Caroline | E7: Arakkonam | I7: 38 | K7: - | M7: Arakkonam
C8: =VLOOKUP(E8,'TN Constituency'!P:Q,2,FALSE) -> 2e887ca2-b947-45eb-8086-fb5e05b9a2ac | D8: Vanniarasu | E8: Tindivanam | I8: 72 | K8: - | M8: Tindivanam
C9: =VLOOKUP(E9,'TN Constituency'!P:Q,2,FALSE) -> 55330759-7d3f-435e-bc45-ef19986b9603 | D9: Malathi | E9: Kallakurichi | I9: 80 | K9: - | M9: Kallakurichi
C10: =VLOOKUP(E10,'TN Constituency'!P:Q,2,FALSE) -> 0ebaae94-0cf3-4cf8-bc48-5256c3119ff1 | D10: Abdul Rahman | E10: Panruti | I10: 154 | K10: - | M10: Panruti
C11: =VLOOKUP(E11,'TN Constituency'!P:Q,2,FALSE) -> 638ea284-7739-40f8-8db7-b26319b8d217 | D11: Jothimani | E11: Kattumannarkoil | I11: 159 | K11: - | M11: Kattumannarkoil(SC)
C12: =VLOOKUP(E12,'TN Constituency'!P:Q,2,FALSE) -> 4686158a-85b8-4b25-b9e3-c0883bd0d13b | D12: Aatral Arasu | E12: Periyakulam | I12: 199 | K12: - | M12: Periyakulam
B14: 15bd812f-51da-41fd-b1e4-80d52b789100
C15: TMC
C16: Sl No. | D16: Candidate name | E16: Constituency name
C17: =VLOOKUP(E17,'TN Constituency'!P:Q,2,FALSE) -> 91bc257e-4e16-4cbe-87e4-bd31f2f58413 | D17: V M Karthikeyan | E17: Ranipet | I17: 41 | K17: - | M17: Ranipet
C18: =VLOOKUP(E18,'TN Constituency'!P:Q,2,FALSE) -> 3a17227d-9feb-4a4c-846b-2ebd9aa172e0 | D18: M. Yuvaraja | E18: Erode (West) | I18: 99 | K18: - | M18: Erode (West)
C19: =VLOOKUP(E19,'TN Constituency'!P:Q,2,FALSE) -> c195167e-8489-4897-bb80-4d1cd317d17e | D19: Vidiyal S Sekar | E19: Oddanchatram | I19: 128 | K19: - | M19: Oddanchatram
C20: =VLOOKUP(E20,'TN Constituency'!P:Q,2,FALSE) -> 846befdb-07b4-4146-abca-c8d1d378a116 | D20: M.K.R. Ashok Kumar | E20: Kumbakonam | I20: 171 | K20: - | M20: Kumbakonam
C21: =VLOOKUP(E21,'TN Constituency'!P:Q,2,FALSE) -> 227183fd-4356-4815-9f2b-51ccced152c5 | D21: Dr J. Nivin Simon | E21: Killiyoor | I21: 234 | K21: - | M21: Killiyoor
B24: 3d1dc59d-7f54-474b-8508-8c3a1bfbd006
C25: IJK
C26: Sl No. | D26: Candidate name | E26: Constituency name
C27: =VLOOKUP(E27,'TN Constituency'!P:Q,2,FALSE) -> e1f1355e-7029-42d4-b661-cfd3139139d6 | D27: Venkatesan | E27: Pallavaram | I27: 30 | K27: - | M27: Pallavaram
C28: =VLOOKUP(E28,'TN Constituency'!P:Q,2,FALSE) -> 93d839a0-f2dc-4bc1-8472-fcea19d24bf6 | D28: Saranya | E28: Kunnam | I28: 148 | K28: - | M28: Kunnam
B31: 8834876e-d88f-406b-85db-f27b165d697b
C32: MDMK
C33: Sl No. | D33: Candidate name | E33: Constituency name
C34: =VLOOKUP(E34,'TN Constituency'!P:Q,2,FALSE) -> ed801607-de07-48d1-b18d-51c1acb399f6 | D34: Senthil Nathan | E34: Modakkurichi | H34: 100 | J34: - | L34: Modakkurichi
C35: =VLOOKUP(E35,'TN Constituency'!P:Q,2,FALSE) -> 338f319d-ca9d-4602-b05d-ecec7b747539 | D35: Senthil Selvan | E35: Sirkazhi | H35: 160 | J35: - | L35: Sirkazhi
C36: =VLOOKUP(E36,'TN Constituency'!P:Q,2,FALSE) -> f392b3e7-f12d-45e3-bd5e-6ff9978c2947 | D36: Boominathan | E36: Madurai South | H36: 192 | J36: - | L36: Madurai South
C37: =VLOOKUP(E37,'TN Constituency'!P:Q,2,FALSE) -> 20e0bb62-3cb1-413b-9452-6d7d72674e55 | D37: Rajendran | E37: Kadayanallur | H37: 221 | J37: - | L37: Kadayanallur

Sheet TN Constituency
G1: assm/parl
D2: id | E2: constituency_id | F2: name | G2: constituency_type | H2: reserved | I2: district_id | J2: state_id | K2: country_id | L2: created_at | M2: created_by | N2: is_active | P2: assembly | Q2: guid
D3: =VLOOKUP(F3,P:Q,2, FALSE) -> ad8f07c3-9b27-47ce-9824-acba45495914 | E3: =VLOOKUP(F3,P:R,3, FALSE) -> 28 | F3: Alandur | G3: assm | I3: 63cbd559-4eec-4e0e-b0fb-6381dfe6c073 | J3: 68628c43-8739-40d7-ab55-923c9a0d6a7d | K3: c81fe682-33a0-11f1-abe6-00155d1e4039 | M3: system | N3: 1 | O3: =_xlfn.CONCAT("insert into constituency (id, name, reserved, district_id, state_id, country_id, created_by) values('", D3, "', '", F3, "', '", H3, "', '", I3, "', '", J3, "', '", K3, "', 'system');") -> insert into constituency (id, name, reserved, district_id, state_id, country_id, created_by) values('ad8f07c3-9b27-47ce-9824-acba45495914', 'Alandur', '', '63cbd559-4eec-4e0e-b0fb-6381dfe6c073', '68628c43-8739-40d7-ab55-923c9a0d6a7d', 'c81fe682-33a0-11f1-abe6-00155d1e4039', 'system'); | P3: Gummidipoondi | Q3: b23bc17c-3c90-42e5-acda-75cbd383845e | R3: 1
D4: =VLOOKUP(F4,P:Q,2, FALSE) -> e07aca0b-7616-4dcd-8664-fa9402b41790 | E4: =VLOOKUP(F4,P:R,3, FALSE) -> 182 | F4: Alangudi | G4: assm | I4: 0fd86ea7-25eb-4f20-b4ad-2fe7dda7e382 | J4: 68628c43-8739-40d7-ab55-923c9a0d6a7d | K4: c81fe682-33a0-11f1-abe6-00155d1e4039 | O4: =_xlfn.CONCAT("insert into constituency (id, name, reserved, district_id, state_id, country_id, created_by) values('", D4, "', '", F4, "', '", H4, "', '", I4, "', '", J4, "', '", K4, "', 'system');") -> insert into constituency (id, name, reserved, district_id, state_id, country_id, created_by) values('e07aca0b-7616-4dcd-8664-fa9402b41790', 'Alangudi', '', '0fd86ea7-25eb-4f20-b4ad-2fe7dda7e382', '68628c43-8739-40d7-ab55-923c9a0d6a7d', 'c81fe682-33a0-11f1-abe6-00155d1e4039', 'system'); | P4: Ponneri | Q4: 3a716a0f-b4b9-457f-a3a1-a66c6888fe7a | R4: 2
D5: =VLOOKUP(F5,P:Q,2, FALSE) -> 5cb2d3dd-3d93-4ead-bc75-569a593ef35c | E5: =VLOOKUP(F5,P:R,3, FALSE) -> 223 | F5: Alangulam | G5: assm | I5: 16857f49-0ac0-41c8-b5f4-b745f6f98fe3 | J5: 68628c43-8739-40d7-ab55-923c9a0d6a7d | K5: c81fe682-33a0-11f1-abe6-00155d1e4039 | O5: =_xlfn.CONCAT("insert into constituency (id, name, reserved, district_id, state_id, country_id, created_by) values('", D5, "', '", F5, "', '", H5, "', '", I5, "', '", J5, "', '", K5, "', 'system');") -> insert into constituency (id, name, reserved, district_id, state_id, country_id, created_by) values('5cb2d3dd-3d93-4ead-bc75-569a593ef35c', 'Alangulam', '', '16857f49-0ac0-41c8-b5f4-b745f6f98fe3', '68628c43-8739-40d7-ab55-923c9a0d6a7d', 'c81fe682-33a0-11f1-abe6-00155d1e4039', 'system'); | P5: Tiruttani | Q5: e0a00a3b-90f6-4696-9e59-caa742168983 | R5: 3
D6: =VLOOKUP(F6,P:Q,2, FALSE) -> 2a795b4b-1a74-43b5-b005-56aeadfa27a1 | E6: =VLOOKUP(F6,P:R,3, FALSE) -> 225 | F6: Ambasamudram | G6: assm | I6: 6a1bb690-7bc3-47d8-9672-e2ba8682155e | J6: 68628c43-8739-40d7-ab55-923c9a0d6a7d | K6: c81fe682-33a0-11f1-abe6-00155d1e4039 | O6: =_xlfn.CONCAT("insert into constituency (id, name, reserved, district_id, state_id, country_id, created_by) values('", D6, "', '", F6, "', '", H6, "', '", I6, "', '", J6, "', '", K6, "', 'system');") -> insert into constituency (id, name, reserved, district_id, state_id, country_id, created_by) values('2a795b4b-1a74-43b5-b005-56aeadfa27a1', 'Ambasamudram', '', '6a1bb690-7bc3-47d8-9672-e2ba8682155e', '68628c43-8739-40d7-ab55-923c9a0d6a7d', 'c81fe682-33a0-11f1-abe6-00155d1e4039', 'system'); | P6: Thiruvallur | Q6: 008aedf6-4a9d-4269-a7ad-63b7e8d8eaa5 | R6: 4
D7: =VLOOKUP(F7,P:Q,2, FALSE) -> bcfb125e-6b85-4f11-a08f-902adff330bf | E7: =VLOOKUP(F7,P:R,3, FALSE) -> 8 | F7: Ambattur | G7: assm | I7: 63cbd559-4eec-4e0e-b0fb-6381dfe6c073 | J7: 68628c43-8739-40d7-ab55-923c9a0d6a7d | K7: c81fe682-33a0-11f1-abe6-00155d1e4039 | O7: =_xlfn.CONCAT("insert into constituency (id, name, reserved, district_id, state_id, country_id, created_by) values('", D7, "', '", F7, "', '", H7, "', '", I7, "', '", J7, "', '", K7, "', 'system');") -> insert into constituency (id, name, reserved, district_id, state_id, country_id, created_by) values('bcfb125e-6b85-4f11-a08f-902adff330bf', 'Ambattur', '', '63cbd559-4eec-4e0e-b0fb-6381dfe6c073', '68628c43-8739-40d7-ab55-923c9a0d6a7d', 'c81fe682-33a0-11f1-abe6-00155d1e4039', 'system'); | P7: Poonamallee | Q7: 17586e3c-1487-43c6-81b0-e3cabe59fa92 | R7: 5
D8: =VLOOKUP(F8,P:Q,2, FALSE) -> 6f8dcb00-c491-4184-a5f0-16d9308fed04 | E8: =VLOOKUP(F8,P:R,3, FALSE) -> 48 | F8: Ambur | G8: assm | I8: 9070969c-1cf1-48f9-b11b-e2e1caf2025d | J8: 68628c43-8739-40d7-ab55-923c9a0d6a7d | K8: c81fe682-33a0-11f1-abe6-00155d1e4039 | O8: =_xlfn.CONCAT("insert into constituency (id, name, reserved, district_id, state_id, country_id, created_by) values('", D8, "', '", F8, "', '", H8, "', '", I8, "', '", J8, "', '", K8, "', 'system');") -> insert into constituency (id, name, reserved, district_id, state_id, country_id, created_by) values('6f8dcb00-c491-4184-a5f0-16d9308fed04', 'Ambur', '', '9070969c-1cf1-48f9-b11b-e2e1caf2025d', '68628c43-8739-40d7-ab55-923c9a0d6a7d', 'c81fe682-33a0-11f1-abe6-00155d1e4039', 'system'); | P8: Avadi | Q8: 4987680d-e88c-4439-a3ae-1a536e586453 | R8: 6
D9: =VLOOKUP(F9,P:Q,2, FALSE) -> ba90a866-2cf6-4c80-8721-b974b597081a | E9: =VLOOKUP(F9,P:R,3, FALSE) -> 44 | F9: Anaikattu | G9: assm | I9: 56ded4ab-571b-4a09-914a-e6c00bd31ee5 | J9: 68628c43-8739-40d7-ab55-923c9a0d6a7d | K9: c81fe682-33a0-11f1-abe6-00155d1e4039 | O9: =_xlfn.CONCAT("insert into constituency (id, name, reserved, district_id, state_id, country_id, created_by) values('", D9, "', '", F9, "', '", H9, "', '", I9, "', '", J9, "', '", K9, "', 'system');") -> insert into constituency (id, name, reserved, district_id, state_id, country_id, created_by) values('ba90a866-2cf6-4c80-8721-b974b597081a', 'Anaikattu', '', '56ded4ab-571b-4a09-914a-e6c00bd31ee5', '68628c43-8739-40d7-ab55-923c9a0d6a7d', 'c81fe682-33a0-11f1-abe6-00155d1e4039', 'system'); | P9: Maduravoyal | Q9: b5f82308-ca4e-41c1-9499-e932b5b6705d | R9: 7
D10: =VLOOKUP(F10,P:Q,2, FALSE) -> aab1c270-b425-4175-8bf6-7aaf06426ba8 | E10: =VLOOKUP(F10,P:R,3, FALSE) -> 198 | F10: Andipatti | G10: assm | I10: 95f7baf3-92ec-4aae-a8d9-7a791a502c75 | J10: 68628c43-8739-40d7-ab55-923c9a0d6a7d | K10: c81fe682-33a0-11f1-abe6-00155d1e4039 | O10: =_xlfn.CONCAT("insert into constituency (id, name, reserved, district_id, state_id, country_id, created_by) values('", D10, "', '", F10, "', '", H10, "', '", I10, "', '", J10, "', '", K10, "', 'system');") -> insert into constituency (id, name, reserved, district_id, state_id, country_id, created_by) values('aab1c270-b425-4175-8bf6-7aaf06426ba8', 'Andipatti', '', '95f7baf3-92ec-4aae-a8d9-7a791a502c75', '68628c43-8739-40d7-ab55-923c9a0d6a7d', 'c81fe682-33a0-11f1-abe6-00155d1e4039', 'system'); | P10: Ambattur | Q10: bcfb125e-6b85-4f11-a08f-902adff330bf | R10: 8
D11: =VLOOKUP(F11,P:Q,2, FALSE) -> 0a5ca5e8-1e73-4ccc-92e4-42d2e7499dc8 | E11: =VLOOKUP(F11,P:R,3, FALSE) -> 21 | F11: Anna Nagar | G11: assm | I11: 63cbd559-4eec-4e0e-b0fb-6381dfe6c073 | J11: 68628c43-8739-40d7-ab55-923c9a0d6a7d | K11: c81fe682-33a0-11f1-abe6-00155d1e4039 | O11: =_xlfn.CONCAT("insert into constituency (id, name, reserved, district_id, state_id, country_id, created_by) values('", D11, "', '", F11, "', '", H11, "', '", I11, "', '", J11, "', '", K11, "', 'system');") -> insert into constituency (id, name, reserved, district_id, state_id, country_id, created_by) values('0a5ca5e8-1e73-4ccc-92e4-42d2e7499dc8', 'Anna Nagar', '', '63cbd559-4eec-4e0e-b0fb-6381dfe6c073', '68628c43-8739-40d7-ab55-923c9a0d6a7d', 'c81fe682-33a0-11f1-abe6-00155d1e4039', 'system'); | P11: Madavaram | Q11: 52619af0-424d-4172-9451-f329734d5a34 | R11: 9
D12: =VLOOKUP(F12,P:Q,2, FALSE) -> 589cd307-7405-4cc3-b8b0-a08530402c7b | E12: =VLOOKUP(F12,P:R,3, FALSE) -> 105 | F12: Anthiyur | G12: assm | I12: e2efd18f-6894-41eb-a8db-08cdb7f21267 | J12: 68628c43-8739-40d7-ab55-923c9a0d6a7d | K12: c81fe682-33a0-11f1-abe6-00155d1e4039 | O12: =_xlfn.CONCAT("insert into constituency (id, name, reserved, district_id, state_id, country_id, created_by) values('", D12, "', '", F12, "', '", H12, "', '", I12, "', '", J12, "', '", K12, "', 'system');") -> insert into constituency (id, name, reserved, district_id, state_id, country_id, created_by) values('589cd307-7405-4cc3-b8b0-a08530402c7b', 'Anthiyur', '', 'e2efd18f-6894-41eb-a8db-08cdb7f21267', '68628c43-8739-40d7-ab55-923c9a0d6a7d', 'c81fe682-33a0-11f1-abe6-00155d1e4039', 'system'); | P12: Thiruvottiyur | Q12: 7ab4491b-648d-48c5-bcac-781f3095e9b3 | R12: 10
D13: =VLOOKUP(F13,P:Q,2, FALSE) -> 3cf53256-ea4a-4536-81f5-78fcf5d61d52 | E13: =VLOOKUP(F13,P:R,3, FALSE) -> 38 | F13: Arakkonam | G13: assm | I13: 4fa55af9-22fb-4523-b6c5-1629a9db82a5 | J13: 68628c43-8739-40d7-ab55-923c9a0d6a7d | K13: c81fe682-33a0-11f1-abe6-00155d1e4039 | O13: =_xlfn.CONCAT("insert into constituency (id, name, reserved, district_id, state_id, country_id, created_by) values('", D13, "', '", F13, "', '", H13, "', '", I13, "', '", J13, "', '", K13, "', 'system');") -> insert into constituency (id, name, reserved, district_id, state_id, country_id, created_by) values('3cf53256-ea4a-4536-81f5-78fcf5d61d52', 'Arakkonam', '', '4fa55af9-22fb-4523-b6c5-1629a9db82a5', '68628c43-8739-40d7-ab55-923c9a0d6a7d', 'c81fe682-33a0-11f1-abe6-00155d1e4039', 'system'); | P13: Dr.Radhakrishnan Nagar | Q13: 499ff327-af5f-4703-8e77-8a22e71fb2c3 | R13: 11
D14: =VLOOKUP(F14,P:Q,2, FALSE) -> 927e8d6e-1528-4cf4-8c57-48ab34fba5f3 | E14: =VLOOKUP(F14,P:R,3, FALSE) -> 67 | F14: Arani | G14: assm | I14: 2fd5e362-8a2e-4b90-8d5f-b71353a07527 | J14: 68628c43-8739-40d7-ab55-923c9a0d6a7d | K14: c81fe682-33a0-11f1-abe6-00155d1e4039 | O14: =_xlfn.CONCAT("insert into constituency (id, name, reserved, district_id, state_id, country_id, created_by) values('", D14, "', '", F14, "', '", H14, "', '", I14, "', '", J14, "', '", K14, "', 'system');") -> insert into constituency (id, name, reserved, district_id, state_id, country_id, created_by) values('927e8d6e-1528-4cf4-8c57-48ab34fba5f3', 'Arani', '', '2fd5e362-8a2e-4b90-8d5f-b71353a07527', '68628c43-8739-40d7-ab55-923c9a0d6a7d', 'c81fe682-33a0-11f1-abe6-00155d1e4039', 'system'); | P14: Perambur | Q14: 144532f7-7933-491e-8f75-8444036f8e76 | R14: 12
D15: =VLOOKUP(F15,P:Q,2, FALSE) -> ad74e248-23ff-4c5f-98e1-805d4ec7e550 | E15: =VLOOKUP(F15,P:R,3, FALSE) -> 183 | F15: Aranthangi | G15: assm | I15: 0fd86ea7-25eb-4f20-b4ad-2fe7dda7e382 | J15: 68628c43-8739-40d7-ab55-923c9a0d6a7d | K15: c81fe682-33a0-11f1-abe6-00155d1e4039 | O15: =_xlfn.CONCAT("insert into constituency (id, name, reserved, district_id, state_id, country_id, created_by) values('", D15, "', '", F15, "', '", H15, "', '", I15, "', '", J15, "', '", K15, "', 'system');") -> insert into constituency (id, name, reserved, district_id, state_id, country_id, created_by) values('ad74e248-23ff-4c5f-98e1-805d4ec7e550', 'Aranthangi', '', '0fd86ea7-25eb-4f20-b4ad-2fe7dda7e382', '68628c43-8739-40d7-ab55-923c9a0d6a7d', 'c81fe682-33a0-11f1-abe6-00155d1e4039', 'system'); | P15: Kolathur | Q15: 3236346d-b10c-4aff-9ce3-c46583b10191 | R15: 13
... D22: =VLOOKUP(F22,P:Q,2, FALSE) -> 4987680d-e88c-4439-a3ae-1a536e586453 | E22: =VLOOKUP(F22,P:R,3, FALSE) -> 6 | F22: Avadi | G22: assm | I22: 76168604-65fc-439f-8e23-05d731626567 | J22: 68628c43-8739-40d7-ab55-923c9a0d6a7d | K22: c81fe682-33a0-11f1-abe6-00155d1e4039 | O22: =_xlfn.CONCAT("insert into constituency (id, name, reserved, district_id, state_id, country_id, created_by) values('", D22, "', '", F22, "', '", H22, "', '", I22, "', '", J22, "', '", K22, "', 'system');") -> insert into constituency (id, name, reserved, district_id, state_id, country_id, created_by) values('4987680d-e88c-4439-a3ae-1a536e586453', 'Avadi', '', '76168604-65fc-439f-8e23-05d731626567', '68628c43-8739-40d7-ab55-923c9a0d6a7d', 'c81fe682-33a0-11f1-abe6-00155d1e4039', 'system'); | P22: Thousand Lights | Q22: c7b04183-9ddf-4099-842a-41042c059d18 | R22: 20
D23: =VLOOKUP(F23,P:Q,2, FALSE) -> f62de6b6-88e3-4238-a22e-ae95a4501718 | E23: =VLOOKUP(F23,P:R,3, FALSE) -> 112 | F23: Avanashi | G23: assm | H23: SC | I23: 13563db6-dce7-4b82-81dd-bac5d416110d | J23: 68628c43-8739-40d7-ab55-923c9a0d6a7d | K23: c81fe682-33a0-11f1-abe6-00155d1e4039 | O23: =_xlfn.CONCAT("insert into constituency (id, name, reserved, district_id, state_id, country_id, created_by) values('", D23, "', '", F23, "', '", H23, "', '", I23, "', '", J23, "', '", K23, "', 'system');") -> insert into constituency (id, name, reserved, district_id, state_id, country_id, created_by) values('f62de6b6-88e3-4238-a22e-ae95a4501718', 'Avanashi', 'SC', '13563db6-dce7-4b82-81dd-bac5d416110d', '68628c43-8739-40d7-ab55-923c9a0d6a7d', 'c81fe682-33a0-11f1-abe6-00155d1e4039', 'system'); | P23: Anna Nagar | Q23: 0a5ca5e8-1e73-4ccc-92e4-42d2e7499dc8 | R23: 21
D24: =VLOOKUP(F24,P:Q,2, FALSE) -> 0f5cf5d2-58cd-4542-9860-aae1fdc6c410 | E24: =VLOOKUP(F24,P:R,3, FALSE) -> 52 | F24: Bargur | G24: assm | I24: 50ffbb0b-1865-4bf1-9af1-2af3f37ff5bd | J24: 68628c43-8739-40d7-ab55-923c9a0d6a7d | K24: c81fe682-33a0-11f1-abe6-00155d1e4039 | O24: =_xlfn.CONCAT("insert into constituency (id, name, reserved, district_id, state_id, country_id, created_by) values('", D24, "', '", F24, "', '", H24, "', '", I24, "', '", J24, "', '", K24, "', 'system');") -> insert into constituency (id, name, reserved, district_id, state_id, country_id, created_by) values('0f5cf5d2-58cd-4542-9860-aae1fdc6c410', 'Bargur', '', '50ffbb0b-1865-4bf1-9af1-2af3f37ff5bd', '68628c43-8739-40d7-ab55-923c9a0d6a7d', 'c81fe682-33a0-11f1-abe6-00155d1e4039', 'system'); | P24: Virugampakkam | Q24: 2b785d52-83bd-45e0-b33d-b931873c69a2 | R24: 22
D25: =VLOOKUP(F25,P:Q,2, FALSE) -> 06b2c95c-e215-4912-8d00-bc09ea3fda45 | E25: =VLOOKUP(F25,P:R,3, FALSE) -> 104 | F25: Bhavani | G25: assm | I25: e2efd18f-6894-41eb-a8db-08cdb7f21267 | J25: 68628c43-8739-40d7-ab55-923c9a0d6a7d | K25: c81fe682-33a0-11f1-abe6-00155d1e4039 | O25: =_xlfn.CONCAT("insert into constituency (id, name, reserved, district_id, state_id, country_id, created_by) values('", D25, "', '", F25, "', '", H25, "', '", I25, "', '", J25, "', '", K25, "', 'system');") -> insert into constituency (id, name, reserved, district_id, state_id, country_id, created_by) values('06b2c95c-e215-4912-8d00-bc09ea3fda45', 'Bhavani', '', 'e2efd18f-6894-41eb-a8db-08cdb7f21267', '68628c43-8739-40d7-ab55-923c9a0d6a7d', 'c81fe682-33a0-11f1-abe6-00155d1e4039', 'system'); | P25: Saidapet | Q25: acfcb782-eb05-4125-84fc-293fdd46247d | R25: 23
D26: =VLOOKUP(F26,P:Q,2, FALSE) -> e3037ea5-dbc9-4532-98fe-073df21856cd | E26: =VLOOKUP(F26,P:R,3, FALSE) -> 107 | F26: Bhavanisagar | G26: assm | I26: e2efd18f-6894-41eb-a8db-08cdb7f21267 | J26: 68628c43-8739-40d7-ab55-923c9a0d6a7d | K26: c81fe682-33a0-11f1-abe6-00155d1e4039 | O26: =_xlfn.CONCAT("insert into constituency (id, name, reserved, district_id, state_id, country_id, created_by) values('", D26, "', '", F26, "', '", H26, "', '", I26, "', '", J26, "', '", K26, "', 'system');") -> insert into constituency (id, name, reserved, district_id, state_id, country_id, created_by) values('e3037ea5-dbc9-4532-98fe-073df21856cd', 'Bhavanisagar', '', 'e2efd18f-6894-41eb-a8db-08cdb7f21267', '68628c43-8739-40d7-ab55-923c9a0d6a7d', 'c81fe682-33a0-11f1-abe6-00155d1e4039', 'system'); | P26: Thiyagarayanagar | Q26: e48776e2-4649-407d-aa1a-b7e535d58691 | R26: 24
D27: =VLOOKUP(F27,P:Q,2, FALSE) -> 69f91b12-f843-4dc2-8355-e32a6033332f | E27: =VLOOKUP(F27,P:R,3, FALSE) -> 157 | F27: Bhuvanagiri | G27: assm | I27: 8e63bc03-1c9e-4f11-bfec-37eea3e8d2d1 | J27: 68628c43-8739-40d7-ab55-923c9a0d6a7d | K27: c81fe682-33a0-11f1-abe6-00155d1e4039 | O27: =_xlfn.CONCAT("insert into constituency (id, name, reserved, district_id, state_id, country_id, created_by) values('", D27, "', '", F27, "', '", H27, "', '", I27, "', '", J27, "', '", K27, "', 'system');") -> insert into constituency (id, name, reserved, district_id, state_id, country_id, created_by) values('69f91b12-f843-4dc2-8355-e32a6033332f', 'Bhuvanagiri', '', '8e63bc03-1c9e-4f11-bfec-37eea3e8d2d1', '68628c43-8739-40d7-ab55-923c9a0d6a7d', 'c81fe682-33a0-11f1-abe6-00155d1e4039', 'system'); | P27: Mylapore | Q27: b3e6de9d-2023-49c1-8579-f087fa71a02a | R27: 25
D28: =VLOOKUP(F28,P:Q,2, FALSE) -> fed1133d-d4ae-49a4-859e-1898f89efa90 | E28: =VLOOKUP(F28,P:R,3, FALSE) -> 200 | F28: Bodinayakanur | G28: assm | I28: 95f7baf3-92ec-4aae-a8d9-7a791a502c75 | J28: 68628c43-8739-40d7-ab55-923c9a0d6a7d | K28: c81fe682-33a0-11f1-abe6-00155d1e4039 | O28: =_xlfn.CONCAT("insert into constituency (id, name, reserved, district_id, state_id, country_id, created_by) values('", D28, "', '", F28, "', '", H28, "', '", I28, "', '", J28, "', '", K28, "', 'system');") -> insert into constituency (id, name, reserved, district_id, state_id, country_id, created_by) values('fed1133d-d4ae-49a4-859e-1898f89efa90', 'Bodinayakanur', '', '95f7baf3-92ec-4aae-a8d9-7a791a502c75', '68628c43-8739-40d7-ab55-923c9a0d6a7d', 'c81fe682-33a0-11f1-abe6-00155d1e4039', 'system'); | P28: Velachery | Q28: c33c5b03-58f9-4026-a61c-d51446248685 | R28: 26
D29: =VLOOKUP(F29,P:Q,2, FALSE) -> 835eaf84-e43d-4adc-8394-432342efb994 | E29: =VLOOKUP(F29,P:R,3, FALSE) -> 32 | F29: Chengalpattu | G29: assm | I29: 33b86357-1153-4e41-9b99-b9685e128df9 | J29: 68628c43-8739-40d7-ab55-923c9a0d6a7d | K29: c81fe682-33a0-11f1-abe6-00155d1e4039 | O29: =_xlfn.CONCAT("insert into constituency (id, name, reserved, district_id, state_id, country_id, created_by) values('", D29, "', '", F29, "', '", H29, "', '", I29, "', '", J29, "', '", K29, "', 'system');") -> insert into constituency (id, name, reserved, district_id, state_id, country_id, created_by) values('835eaf84-e43d-4adc-8394-432342efb994', 'Chengalpattu', '', '33b86357-1153-4e41-9b99-b9685e128df9', '68628c43-8739-40d7-ab55-923c9a0d6a7d', 'c81fe682-33a0-11f1-abe6-00155d1e4039', 'system'); | P29: Shozhinganallur | Q29: bd9d5fa4-c604-4d86-b4a7-e587bdb4deeb | R29: 27
D30: =VLOOKUP(F30,P:Q,2, FALSE) -> c78ce47e-2e7c-407f-ab81-9dab38ea9afc | E30: =VLOOKUP(F30,P:R,3, FALSE) -> 62 | F30: Chengam | G30: assm | I30: 2fd5e362-8a2e-4b90-8d5f-b71353a07527 | J30: 68628c43-8739-40d7-ab55-923c9a0d6a7d | K30: c81fe682-33a0-11f1-abe6-00155d1e4039 | O30: =_xlfn.CONCAT("insert into constituency (id, name, reserved, district_id, state_id, country_id, created_by) values('", D30, "', '", F30, "', '", H30, "', '", I30, "', '", J30, "', '", K30, "', 'system');") -> insert into constituency (id, name, reserved, district_id, state_id, country_id, created_by) values('c78ce47e-2e7c-407f-ab81-9dab38ea9afc', 'Chengam', '', '2fd5e362-8a2e-4b90-8d5f-b71353a07527', '68628c43-8739-40d7-ab55-923c9a0d6a7d', 'c81fe682-33a0-11f1-abe6-00155d1e4039', 'system'); | P30: Alandur | Q30: ad8f07c3-9b27-47ce-9824-acba45495914 | R30: 28
D31: =VLOOKUP(F31,P:Q,2, FALSE) -> 9f1f5173-0700-4a12-ae6b-23e4b140e8a7 | E31: =VLOOKUP(F31,P:R,3, FALSE) -> 19 | F31: Chepauk-Thiruvallikeni | G31: assm | I31: 63cbd559-4eec-4e0e-b0fb-6381dfe6c073 | J31: 68628c43-8739-40d7-ab55-923c9a0d6a7d | K31: c81fe682-33a0-11f1-abe6-00155d1e4039 | O31: =_xlfn.CONCAT("insert into constituency (id, name, reserved, district_id, state_id, country_id, created_by) values('", D31, "', '", F31, "', '", H31, "', '", I31, "', '", J31, "', '", K31, "', 'system');") -> insert into constituency (id, name, reserved, district_id, state_id, country_id, created_by) values('9f1f5173-0700-4a12-ae6b-23e4b140e8a7', 'Chepauk-Thiruvallikeni', '', '63cbd559-4eec-4e0e-b0fb-6381dfe6c073', '68628c43-8739-40d7-ab55-923c9a0d6a7d', 'c81fe682-33a0-11f1-abe6-00155d1e4039', 'system'); | P31: Sriperumbudur | Q31: c6a5fdc0-2b60-4dd6-8dc5-4bfe43d62eb8 | R31: 29
D32: =VLOOKUP(F32,P:Q,2, FALSE) -> 05a929a2-e037-4326-9ca6-edd4a07104da | E32: =VLOOKUP(F32,P:R,3, FALSE) -> 68 | F32: Cheyyar | G32: assm | I32: 2fd5e362-8a2e-4b90-8d5f-b71353a07527 | J32: 68628c43-8739-40d7-ab55-923c9a0d6a7d | K32: c81fe682-33a0-11f1-abe6-00155d1e4039 | O32: =_xlfn.CONCAT("insert into constituency (id, name, reserved, district_id, state_id, country_id, created_by) values('", D32, "', '", F32, "', '", H32, "', '", I32, "', '", J32, "', '", K32, "', 'system');") -> insert into constituency (id, name, reserved, district_id, state_id, country_id, created_by) values('05a929a2-e037-4326-9ca6-edd4a07104da', 'Cheyyar', '', '2fd5e362-8a2e-4b90-8d5f-b71353a07527', '68628c43-8739-40d7-ab55-923c9a0d6a7d', 'c81fe682-33a0-11f1-abe6-00155d1e4039', 'system'); | P32: Pallavaram | Q32: e1f1355e-7029-42d4-b661-cfd3139139d6 | R32: 30
D33: =VLOOKUP(F33,P:Q,2, FALSE) -> 92c11a80-61bf-41d8-ac06-ccda1453a110 | E33: =VLOOKUP(F33,P:R,3, FALSE) -> 34 | F33: Cheyyur | G33: assm | I33: 33b86357-1153-4e41-9b99-b9685e128df9 | J33: 68628c43-8739-40d7-ab55-923c9a0d6a7d | K33: c81fe682-33a0-11f1-abe6-00155d1e4039 | O33: =_xlfn.CONCAT("insert into constituency (id, name, reserved, district_id, state_id, country_id, created_by) values('", D33, "', '", F33, "', '", H33, "', '", I33, "', '", J33, "', '", K33, "', 'system');") -> insert into constituency (id, name, reserved, district_id, state_id, country_id, created_by) values('92c11a80-61bf-41d8-ac06-ccda1453a110', 'Cheyyur', '', '33b86357-1153-4e41-9b99-b9685e128df9', '68628c43-8739-40d7-ab55-923c9a0d6a7d', 'c81fe682-33a0-11f1-abe6-00155d1e4039', 'system'); | P33: Tambaram | Q33: 3ce24248-60ae-4e11-b3da-71b847a02cea | R33: 31
D34: =VLOOKUP(F34,P:Q,2, FALSE) -> 3e7a7e53-c838-4876-af14-fa1052bb13b2 | E34: =VLOOKUP(F34,P:R,3, FALSE) -> 158 | F34: Chidambaram | G34: assm | I34: 8e63bc03-1c9e-4f11-bfec-37eea3e8d2d1 | J34: 68628c43-8739-40d7-ab55-923c9a0d6a7d | K34: c81fe682-33a0-11f1-abe6-00155d1e4039 | O34: =_xlfn.CONCAT("insert into constituency (id, name, reserved, district_id, state_id, country_id, created_by) values('", D34, "', '", F34, "', '", H34, "', '", I34, "', '", J34, "', '", K34, "', 'system');") -> insert into constituency (id, name, reserved, district_id, state_id, country_id, created_by) values('3e7a7e53-c838-4876-af14-fa1052bb13b2', 'Chidambaram', '', '8e63bc03-1c9e-4f11-bfec-37eea3e8d2d1', '68628c43-8739-40d7-ab55-923c9a0d6a7d', 'c81fe682-33a0-11f1-abe6-00155d1e4039', 'system'); | P34: Chengalpattu | Q34: 835eaf84-e43d-4adc-8394-432342efb994 | R34: 32
D35: =VLOOKUP(F35,P:Q,2, FALSE) -> 4eb64a68-0a3a-4e72-8e80-bd74ed85e060 | E35: =VLOOKUP(F35,P:R,3, FALSE) -> 118 | F35: Coimbatore (North) | G35: assm | I35: fadd0541-32fa-4fb6-928b-1c74a1fd8686 | J35: 68628c43-8739-40d7-ab55-923c9a0d6a7d | K35: c81fe682-33a0-11f1-abe6-00155d1e4039 | O35: =_xlfn.CONCAT("insert into constituency (id, name, reserved, district_id, state_id, country_id, created_by) values('", D35, "', '", F35, "', '", H35, "', '", I35, "', '", J35, "', '", K35, "', 'system');") -> insert into constituency (id, name, reserved, district_id, state_id, country_id, created_by) values('4eb64a68-0a3a-4e72-8e80-bd74ed85e060', 'Coimbatore (North)', '', 'fadd0541-32fa-4fb6-928b-1c74a1fd8686', '68628c43-8739-40d7-ab55-923c9a0d6a7d', 'c81fe682-33a0-11f1-abe6-00155d1e4039', 'system'); | P35: Thiruporur | Q35: 8bf639a7-bca3-42f8-928c-d466c5679fd8 | R35: 33
... D40: =VLOOKUP(F40,P:Q,2, FALSE) -> 121a1dbb-3e2b-49a2-a113-f53d3c9393f7 | E40: =VLOOKUP(F40,P:R,3, FALSE) -> 201 | F40: Cumbum | G40: assm | I40: 95f7baf3-92ec-4aae-a8d9-7a791a502c75 | J40: 68628c43-8739-40d7-ab55-923c9a0d6a7d | K40: c81fe682-33a0-11f1-abe6-00155d1e4039 | O40: =_xlfn.CONCAT("insert into constituency (id, name, reserved, district_id, state_id, country_id, created_by) values('", D40, "', '", F40, "', '", H40, "', '", I40, "', '", J40, "', '", K40, "', 'system');") -> insert into constituency (id, name, reserved, district_id, state_id, country_id, created_by) values('121a1dbb-3e2b-49a2-a113-f53d3c9393f7', 'Cumbum', '', '95f7baf3-92ec-4aae-a8d9-7a791a502c75', '68628c43-8739-40d7-ab55-923c9a0d6a7d', 'c81fe682-33a0-11f1-abe6-00155d1e4039', 'system'); | P40: Arakkonam | Q40: 3cf53256-ea4a-4536-81f5-78fcf5d61d52 | R40: 38
D41: =VLOOKUP(F41,P:Q,2, FALSE) -> fa9c0257-3e31-49db-a50c-7b979887595b | E41: =VLOOKUP(F41,P:R,3, FALSE) -> 101 | F41: Dharapuram | G41: assm | H41: SC | I41: 13563db6-dce7-4b82-81dd-bac5d416110d | J41: 68628c43-8739-40d7-ab55-923c9a0d6a7d | K41: c81fe682-33a0-11f1-abe6-00155d1e4039 | O41: =_xlfn.CONCAT("insert into constituency (id, name, reserved, district_id, state_id, country_id, created_by) values('", D41, "', '", F41, "', '", H41, "', '", I41, "', '", J41, "', '", K41, "', 'system');") -> insert into constituency (id, name, reserved, district_id, state_id, country_id, created_by) values('fa9c0257-3e31-49db-a50c-7b979887595b', 'Dharapuram', 'SC', '13563db6-dce7-4b82-81dd-bac5d416110d', '68628c43-8739-40d7-ab55-923c9a0d6a7d', 'c81fe682-33a0-11f1-abe6-00155d1e4039', 'system'); | P41: Sholingur | Q41: b4afca63-3c36-494b-8f7a-308c74d24ef3 | R41: 39
D42: =VLOOKUP(F42,P:Q,2, FALSE) -> 336dc71b-ba67-4fd9-9c9c-8289c709cdf5 | E42: =VLOOKUP(F42,P:R,3, FALSE) -> 59 | F42: Dharmapuri | G42: assm | I42: 3a93651e-764f-48f3-8748-25b303c32304 | J42: 68628c43-8739-40d7-ab55-923c9a0d6a7d | K42: c81fe682-33a0-11f1-abe6-00155d1e4039 | O42: =_xlfn.CONCAT("insert into constituency (id, name, reserved, district_id, state_id, country_id, created_by) values('", D42, "', '", F42, "', '", H42, "', '", I42, "', '", J42, "', '", K42, "', 'system');") -> insert into constituency (id, name, reserved, district_id, state_id, country_id, created_by) values('336dc71b-ba67-4fd9-9c9c-8289c709cdf5', 'Dharmapuri', '', '3a93651e-764f-48f3-8748-25b303c32304', '68628c43-8739-40d7-ab55-923c9a0d6a7d', 'c81fe682-33a0-11f1-abe6-00155d1e4039', 'system'); | P42: Katpadi | Q42: 7d3c2063-3254-4d91-87ba-94a938cd420d | R42: 40
D43: =VLOOKUP(F43,P:Q,2, FALSE) -> 1b37722d-13a6-4ab0-95c1-bcd69378af2a | E43: =VLOOKUP(F43,P:R,3, FALSE) -> 132 | F43: Dindigul | G43: assm | I43: 69483f23-6312-4c39-826f-a058c83f421a | J43: 68628c43-8739-40d7-ab55-923c9a0d6a7d | K43: c81fe682-33a0-11f1-abe6-00155d1e4039 | O43: =_xlfn.CONCAT("insert into constituency (id, name, reserved, district_id, state_id, country_id, created_by) values('", D43, "', '", F43, "', '", H43, "', '", I43, "', '", J43, "', '", K43, "', 'system');") -> insert into constituency (id, name, reserved, district_id, state_id, country_id, created_by) values('1b37722d-13a6-4ab0-95c1-bcd69378af2a', 'Dindigul', '', '69483f23-6312-4c39-826f-a058c83f421a', '68628c43-8739-40d7-ab55-923c9a0d6a7d', 'c81fe682-33a0-11f1-abe6-00155d1e4039', 'system'); | P43: Ranipet | Q43: 91bc257e-4e16-4cbe-87e4-bd31f2f58413 | R43: 41
D44: =VLOOKUP(F44,P:Q,2, FALSE) -> 499ff327-af5f-4703-8e77-8a22e71fb2c3 | E44: =VLOOKUP(F44,P:R,3, FALSE) -> 11 | F44: Dr.Radhakrishnan Nagar | G44: assm | I44: 63cbd559-4eec-4e0e-b0fb-6381dfe6c073 | J44: 68628c43-8739-40d7-ab55-923c9a0d6a7d | K44: c81fe682-33a0-11f1-abe6-00155d1e4039 | O44: =_xlfn.CONCAT("insert into constituency (id, name, reserved, district_id, state_id, country_id, created_by) values('", D44, "', '", F44, "', '", H44, "', '", I44, "', '", J44, "', '", K44, "', 'system');") -> insert into constituency (id, name, reserved, district_id, state_id, country_id, created_by) values('499ff327-af5f-4703-8e77-8a22e71fb2c3', 'Dr.Radhakrishnan Nagar', '', '63cbd559-4eec-4e0e-b0fb-6381dfe6c073', '68628c43-8739-40d7-ab55-923c9a0d6a7d', 'c81fe682-33a0-11f1-abe6-00155d1e4039', 'system'); | P44: Arcot | Q44: 69fa24d2-050d-453c-9541-b00de0eddc10 | R44: 42
